2025-01-26 13:22:53,733 - tests.test_app - ERROR - test_app.py:65 - Error in page initialization test: assert False
 +  where False = <MagicMock name='set_page_config' id='2517518243776'>.called
2025-01-26 13:22:53,759 - tests.test_app - ERROR - test_app.py:78 - Error in model selection test: assert False
 +  where False = <MagicMock name='selectbox' id='2517517980288'>.called
2025-01-26 13:22:53,779 - tests.test_app - ERROR - test_app.py:92 - Error in sample tasks test: st.session_state has no attribute "user_input". Did you forget to initialize it? More info: https://docs.streamlit.io/develop/concepts/architecture/session-state#initialization
2025-01-26 13:22:53,996 - tests.test_app - ERROR - test_app.py:119 - Error in process request test: name 'process_request' is not defined
2025-01-26 13:22:54,028 - tests.test_app - ERROR - test_app.py:138 - Error in error handling test: assert False
 +  where False = <MagicMock name='error' id='2517516645008'>.called
2025-01-26 13:22:54,059 - tests.test_app - ERROR - test_app.py:172 - Error in UI components visibility test: assert False
 +  where False = <MagicMock name='title' id='2517518568336'>.called
2025-01-26 13:22:54,186 - tests.test_llm - ERROR - test_llm.py:61 - Error in list_available_models test: Error listing Ollama models: 'model'
2025-01-26 13:22:54,314 - task_manager - ERROR - task_manager.py:125 - Error in planner: Error communicating with Ollama: 1 validation error for Message
role
  Field required [type=missing, input_value={'content': 'You are a pl...eps.', 'type': 'system'}, input_type=dict]
    For further information visit https://errors.pydantic.dev/2.10/v/missing
Traceback (most recent call last):
  File "C:\Users\denni\Documents\personal-ai-task-assistant\src\llm.py", line 26, in chat_with_ollama
    response = ollama.chat(
               ^^^^^^^^^^^^
  File "C:\Users\denni\AppData\Roaming\Python\Python312\site-packages\ollama\_client.py", line 338, in chat
    messages=[message for message in _copy_messages(messages)],
                                     ^^^^^^^^^^^^^^^^^^^^^^^^
  File "C:\Users\denni\AppData\Roaming\Python\Python312\site-packages\ollama\_client.py", line 1131, in _copy_messages
    yield Message.model_validate(
          ^^^^^^^^^^^^^^^^^^^^^^^
  File "C:\Users\denni\AppData\Roaming\Python\Python312\site-packages\pydantic\main.py", line 627, in model_validate
    return cls.__pydantic_validator__.validate_python(
           ^^^^^^^^^^^^^^^^^^^^^^^^^^^^^^^^^^^^^^^^^^^
pydantic_core._pydantic_core.ValidationError: 1 validation error for Message
role
  Field required [type=missing, input_value={'content': 'You are a pl...eps.', 'type': 'system'}, input_type=dict]
    For further information visit https://errors.pydantic.dev/2.10/v/missing

During handling of the above exception, another exception occurred:

Traceback (most recent call last):
  File "C:\Users\denni\Documents\personal-ai-task-assistant\src\task_manager.py", line 111, in planner
    result = llm(prompt.format_messages())
             ^^^^^^^^^^^^^^^^^^^^^^^^^^^^^
  File "C:\Users\denni\Documents\personal-ai-task-assistant\src\llm.py", line 36, in chat_with_ollama
    raise RuntimeError(f"Error communicating with Ollama: {str(e)}")
RuntimeError: Error communicating with Ollama: 1 validation error for Message
role
  Field required [type=missing, input_value={'content': 'You are a pl...eps.', 'type': 'system'}, input_type=dict]
    For further information visit https://errors.pydantic.dev/2.10/v/missing
2025-01-26 13:22:54,360 - tests.test_task_manager - ERROR - test_task_manager.py:120 - Error in planner test: Error communicating with Ollama: 1 validation error for Message
role
  Field required [type=missing, input_value={'content': 'You are a pl...eps.', 'type': 'system'}, input_type=dict]
    For further information visit https://errors.pydantic.dev/2.10/v/missing
2025-01-26 13:22:54,502 - task_manager - ERROR - task_manager.py:197 - Error in task_executor: Error communicating with Ollama: 1 validation error for Message
role
  Field required [type=missing, input_value={'content': 'You are a he...sks.', 'type': 'system'}, input_type=dict]
    For further information visit https://errors.pydantic.dev/2.10/v/missing
Traceback (most recent call last):
  File "C:\Users\denni\Documents\personal-ai-task-assistant\src\llm.py", line 26, in chat_with_ollama
    response = ollama.chat(
               ^^^^^^^^^^^^
  File "C:\Users\denni\AppData\Roaming\Python\Python312\site-packages\ollama\_client.py", line 338, in chat
    messages=[message for message in _copy_messages(messages)],
                                     ^^^^^^^^^^^^^^^^^^^^^^^^
  File "C:\Users\denni\AppData\Roaming\Python\Python312\site-packages\ollama\_client.py", line 1131, in _copy_messages
    yield Message.model_validate(
          ^^^^^^^^^^^^^^^^^^^^^^^
  File "C:\Users\denni\AppData\Roaming\Python\Python312\site-packages\pydantic\main.py", line 627, in model_validate
    return cls.__pydantic_validator__.validate_python(
           ^^^^^^^^^^^^^^^^^^^^^^^^^^^^^^^^^^^^^^^^^^^
pydantic_core._pydantic_core.ValidationError: 1 validation error for Message
role
  Field required [type=missing, input_value={'content': 'You are a he...sks.', 'type': 'system'}, input_type=dict]
    For further information visit https://errors.pydantic.dev/2.10/v/missing

During handling of the above exception, another exception occurred:

Traceback (most recent call last):
  File "C:\Users\denni\Documents\personal-ai-task-assistant\src\task_manager.py", line 157, in task_executor
    result = llm(messages)
             ^^^^^^^^^^^^^
  File "C:\Users\denni\Documents\personal-ai-task-assistant\src\llm.py", line 36, in chat_with_ollama
    raise RuntimeError(f"Error communicating with Ollama: {str(e)}")
RuntimeError: Error communicating with Ollama: 1 validation error for Message
role
  Field required [type=missing, input_value={'content': 'You are a he...sks.', 'type': 'system'}, input_type=dict]
    For further information visit https://errors.pydantic.dev/2.10/v/missing
2025-01-26 13:22:54,516 - task_manager - ERROR - task_manager.py:291 - Error in replanner: Error communicating with Ollama: 1 validation error for Message
role
  Field required [type=missing, input_value={'content': 'You are a re...ete.', 'type': 'system'}, input_type=dict]
    For further information visit https://errors.pydantic.dev/2.10/v/missing
Traceback (most recent call last):
  File "C:\Users\denni\Documents\personal-ai-task-assistant\src\llm.py", line 26, in chat_with_ollama
    response = ollama.chat(
               ^^^^^^^^^^^^
  File "C:\Users\denni\AppData\Roaming\Python\Python312\site-packages\ollama\_client.py", line 338, in chat
    messages=[message for message in _copy_messages(messages)],
                                     ^^^^^^^^^^^^^^^^^^^^^^^^
  File "C:\Users\denni\AppData\Roaming\Python\Python312\site-packages\ollama\_client.py", line 1131, in _copy_messages
    yield Message.model_validate(
          ^^^^^^^^^^^^^^^^^^^^^^^
  File "C:\Users\denni\AppData\Roaming\Python\Python312\site-packages\pydantic\main.py", line 627, in model_validate
    return cls.__pydantic_validator__.validate_python(
           ^^^^^^^^^^^^^^^^^^^^^^^^^^^^^^^^^^^^^^^^^^^
pydantic_core._pydantic_core.ValidationError: 1 validation error for Message
role
  Field required [type=missing, input_value={'content': 'You are a re...ete.', 'type': 'system'}, input_type=dict]
    For further information visit https://errors.pydantic.dev/2.10/v/missing

During handling of the above exception, another exception occurred:

Traceback (most recent call last):
  File "C:\Users\denni\Documents\personal-ai-task-assistant\src\task_manager.py", line 269, in replanner
    result = llm(messages)
             ^^^^^^^^^^^^^
  File "C:\Users\denni\Documents\personal-ai-task-assistant\src\llm.py", line 36, in chat_with_ollama
    raise RuntimeError(f"Error communicating with Ollama: {str(e)}")
RuntimeError: Error communicating with Ollama: 1 validation error for Message
role
  Field required [type=missing, input_value={'content': 'You are a re...ete.', 'type': 'system'}, input_type=dict]
    For further information visit https://errors.pydantic.dev/2.10/v/missing
2025-01-26 13:22:54,518 - tests.test_task_manager - ERROR - test_task_manager.py:163 - Error in replanner test: assert False
 +  where False = isinstance({'context': {'model_id': 'test-model'}, 'current_node': 'task_executor', 'goals': 'Test goal', 'next_task': None, ...}, AgentFinish)
2025-01-26 13:22:54,542 - task_manager - ERROR - task_manager.py:125 - Error in planner: Error communicating with Ollama: 1 validation error for Message
role
  Field required [type=missing, input_value={'content': 'You are a pl...eps.', 'type': 'system'}, input_type=dict]
    For further information visit https://errors.pydantic.dev/2.10/v/missing
Traceback (most recent call last):
  File "C:\Users\denni\Documents\personal-ai-task-assistant\src\llm.py", line 26, in chat_with_ollama
    response = ollama.chat(
               ^^^^^^^^^^^^
  File "C:\Users\denni\AppData\Roaming\Python\Python312\site-packages\ollama\_client.py", line 338, in chat
    messages=[message for message in _copy_messages(messages)],
                                     ^^^^^^^^^^^^^^^^^^^^^^^^
  File "C:\Users\denni\AppData\Roaming\Python\Python312\site-packages\ollama\_client.py", line 1131, in _copy_messages
    yield Message.model_validate(
          ^^^^^^^^^^^^^^^^^^^^^^^
  File "C:\Users\denni\AppData\Roaming\Python\Python312\site-packages\pydantic\main.py", line 627, in model_validate
    return cls.__pydantic_validator__.validate_python(
           ^^^^^^^^^^^^^^^^^^^^^^^^^^^^^^^^^^^^^^^^^^^
pydantic_core._pydantic_core.ValidationError: 1 validation error for Message
role
  Field required [type=missing, input_value={'content': 'You are a pl...eps.', 'type': 'system'}, input_type=dict]
    For further information visit https://errors.pydantic.dev/2.10/v/missing

During handling of the above exception, another exception occurred:

Traceback (most recent call last):
  File "C:\Users\denni\Documents\personal-ai-task-assistant\src\task_manager.py", line 111, in planner
    result = llm(prompt.format_messages())
             ^^^^^^^^^^^^^^^^^^^^^^^^^^^^^
  File "C:\Users\denni\Documents\personal-ai-task-assistant\src\llm.py", line 36, in chat_with_ollama
    raise RuntimeError(f"Error communicating with Ollama: {str(e)}")
RuntimeError: Error communicating with Ollama: 1 validation error for Message
role
  Field required [type=missing, input_value={'content': 'You are a pl...eps.', 'type': 'system'}, input_type=dict]
    For further information visit https://errors.pydantic.dev/2.10/v/missing
2025-01-26 13:22:54,544 - task_manager - ERROR - task_manager.py:362 - Error occurred in run_paa: Error communicating with Ollama: 1 validation error for Message
role
  Field required [type=missing, input_value={'content': 'You are a pl...eps.', 'type': 'system'}, input_type=dict]
    For further information visit https://errors.pydantic.dev/2.10/v/missing
Traceback (most recent call last):
  File "C:\Users\denni\Documents\personal-ai-task-assistant\src\llm.py", line 26, in chat_with_ollama
    response = ollama.chat(
               ^^^^^^^^^^^^
  File "C:\Users\denni\AppData\Roaming\Python\Python312\site-packages\ollama\_client.py", line 338, in chat
    messages=[message for message in _copy_messages(messages)],
                                     ^^^^^^^^^^^^^^^^^^^^^^^^
  File "C:\Users\denni\AppData\Roaming\Python\Python312\site-packages\ollama\_client.py", line 1131, in _copy_messages
    yield Message.model_validate(
          ^^^^^^^^^^^^^^^^^^^^^^^
  File "C:\Users\denni\AppData\Roaming\Python\Python312\site-packages\pydantic\main.py", line 627, in model_validate
    return cls.__pydantic_validator__.validate_python(
           ^^^^^^^^^^^^^^^^^^^^^^^^^^^^^^^^^^^^^^^^^^^
pydantic_core._pydantic_core.ValidationError: 1 validation error for Message
role
  Field required [type=missing, input_value={'content': 'You are a pl...eps.', 'type': 'system'}, input_type=dict]
    For further information visit https://errors.pydantic.dev/2.10/v/missing

During handling of the above exception, another exception occurred:

Traceback (most recent call last):
  File "C:\Users\denni\Documents\personal-ai-task-assistant\src\task_manager.py", line 317, in run_paa
    current_state = planner(current_state)
                    ^^^^^^^^^^^^^^^^^^^^^^
  File "C:\Users\denni\Documents\personal-ai-task-assistant\src\task_manager.py", line 111, in planner
    result = llm(prompt.format_messages())
             ^^^^^^^^^^^^^^^^^^^^^^^^^^^^^
  File "C:\Users\denni\Documents\personal-ai-task-assistant\src\llm.py", line 36, in chat_with_ollama
    raise RuntimeError(f"Error communicating with Ollama: {str(e)}")
RuntimeError: Error communicating with Ollama: 1 validation error for Message
role
  Field required [type=missing, input_value={'content': 'You are a pl...eps.', 'type': 'system'}, input_type=dict]
    For further information visit https://errors.pydantic.dev/2.10/v/missing
2025-01-26 13:22:54,548 - tests.test_task_manager - ERROR - test_task_manager.py:179 - Error in run_paa test: assert 'current_node' in {'error': "Error communicating with Ollama: 1 validation error for Message\nrole\n  Field required [type=missing, input_value={'content': 'You are a pl...eps.', 'type': 'system'}, input_type=dict]\n    For further information visit https://errors.pydantic.dev/2.10/v/missing"}
2025-01-26 13:22:54,578 - task_manager - ERROR - task_manager.py:197 - Error in task_executor: 'goals'
Traceback (most recent call last):
  File "C:\Users\denni\Documents\personal-ai-task-assistant\src\task_manager.py", line 155, in task_executor
    task=state["current_task"], goal=state["goals"]
                                     ~~~~~^^^^^^^^^
KeyError: 'goals'
